Workbook

Sheet Menkul Kıymet
A1: Tarih | B1: Hisse Senedi Stok | C1: DİBS STOK | D1: Repo Stok | E1: ÖSBA STOK | I1: Hisse Senedi Flow | J1: DIBS Flow | K1: REPO Flow | L1: OSBA Flow | O1: Eurobond | P1: Hazine Eurobond Stok | Q1: Hazine Eurobond Flow | S1: Şirket Eurobond Stok | T1: Şirket Eurobond Flow
A2: 04-05-2018 | B2: TP.PYUK1 | C2: TP.PYUK2 | D2: TP.PYUK21 | E2: TP.PYUK22 | I2: TP.PYUK3 | J2: TP.PYUK4 | K2: TP.PYUK5 | L2: TP.PYUK5 | P2: TP.BS07.CARI | Q2: TP.BS07.NOMINAL | S2: TP.HDBSC.K7 | T2: TP.HDBSN.K7
A3: 11-05-2018 | B3: 40832.5 | C3: 27101.3 | D3: 1941.1 | E3: 876.9 | I3: 28.8 | J3: -230.9 | K3: -24.8 | L3: -5.8 | P3: 44522.5 | Q3: 45876.1 | S3: TP.HDBSC.K18 | T3: TP.HDBSN.K18
A4: 18-05-2018 | B4: 39586.5 | C4: 24693.6 | D4: 1820.7 | E4: 835.5 | I4: -72 | J4: -637.9 | K4: -26.2 | L4: -41.5 | P4: 43152.1 | Q4: 45743.6 | S4: TP.HDBSC.K29 | T4: TP.HDBSN.K29
A5: 25-05-2018 | B5: 37480 | C5: 23252.9 | D5: 1718.4 | E5: 789.6 | I5: -9.4 | J5: -144.3 | K5: -4.8 | L5: -45.9 | P5: 44093 | Q5: 45811.5 | S5: 45791.36 | T5: 0
A6: 01-06-2018 | B6: 38096.5 | C6: 24828.5 | D6: 1780.2 | E6: 767.1 | I6: 15 | J6: 29.4 | K6: -31.3 | L6: -22.5 | P6: 43224.7 | Q6: 45445.6 | S6: 45712.58 | T6: 0
A7: 08-06-2018 | B7: 36210.3 | C7: 23662.5 | D7: 2594 | E7: 779.1 | I7: -218.6 | J7: -170.9 | K7: 843.7 | L7: 12 | P7: 43829.5 | Q7: 46004.6 | S7: 45775.17 | T7: 0
A8: 15-06-2018 | B8: 34839 | C8: 22298.3 | D8: 1717.2 | E8: 753.7 | I8: 289.1 | J8: -459.5 | K8: -815.5 | L8: -25.4 | P8: 42984.8 | Q8: 45680.8 | S8: 44862.32 | T8: 48064.27
A9: 22-06-2018 | B9: 34921.4 | C9: 21695.5 | D9: 1622.1 | E9: 756.3 | I9: 225.4 | J9: 131.5 | K9: -54 | L9: 2.6 | P9: 43469.7 | Q9: 45781.9 | S9: 44733.92 | T9: 47752.94
A10: 29-06-2018 | B10: 36121.6 | C10: 22403 | D10: 1672.2 | E10: 781.6 | I10: -179.8 | J10: 83.2 | K10: -10.1 | L10: 25.3 | P10: 43398.1 | Q10: 45750.3 | S10: 44756.86 | T10: 47730.59
A11: 06-07-2018 | B11: 36279.8 | C11: 22280.8 | D11: 1663.3 | E11: 766.6 | I11: -80.8 | J11: 397.4 | K11: 0.7 | L11: -15 | P11: 43877.6 | Q11: 45863.4 | S11: 44899.8 | T11: 47793.82
A12: 13-07-2018 | B12: 32781.1 | C12: 20552.3 | D12: 1598.3 | E12: 727.9 | I12: -213.8 | J12: 49.4 | K12: -0.2 | L12: -38.8 | P12: 42442.1 | Q12: 45510.8 | S12: 43791.26 | T12: 47657.21
A13: 20-07-2018 | B13: 31192.5 | C13: 20500 | D13: 1593.4 | E13: 773.6 | I13: -222.2 | J13: -256.4 | K13: -0.3 | L13: 45.7 | P13: 43293.4 | Q13: 45765.8 | S13: 44007.76 | T13: 47563.58
A14: 27-07-2018 | B14: 32564.2 | C14: 20376.5 | D14: 1593.4 | E14: 769.4 | I14: 28.3 | J14: -18.2 | K14: 0.6 | L14: -4.2 | P14: 43048.5 | Q14: 45758.7 | S14: 44016.37 | T14: 47595.61
A15: 03-08-2018 | B15: 31645.1 | C15: 18622.3 | D15: 1517 | E15: 715.9 | I15: 77.6 | J15: -182.1 | K15: 4.4 | L15: -53.5 | P15: 42466.2 | Q15: 45691.9 | S15: 42623.31 | T15: 47083.78
A16: 10-08-2018 | B16: 29363.1 | C16: 17078.8 | D16: 1445.5 | E16: 671.4 | I16: 45.8 | J16: -196.5 | K16: 21.4 | L16: -44.5 | P16: 40298.9 | Q16: 45725.8 | S16: 40046.7 | T16: 46763.08
... A133: 06-11-2020 | B133: 19728.6 | C133: 4960.2 | D133: 131.4 | E133: 212.2 | I133: -22 | J133: -4.5 | K133: 5.1 | L133: -9.1 | P133: 43703.7 | Q133: 46402 | S133: 36129.01 | T133: 37391.31
A134: 13-11-2020 | B134: 23507.6 | C134: 5803.8 | D134: 166.9 | E134: 232 | I134: 614.4 | J134: 293.9 | K134: 22.9 | L134: 19.8 | P134: 46119.8 | Q134: 46415 | S134: 36951.64 | T134: 37662.08 | V134: 6 Kasım Sonrası Flow
A135: 20-11-2020 | B135: 25306.8 | C135: 6151.8 | D135: 234.4 | E135: 239.2 | I135: 389.6 | J135: 175.5 | K135: 64.1 | L135: 7.2 | P135: 46319.6 | Q135: 46274.7 | S135: 37173.91 | T135: 37597.57 | V135: Hisse Flow
A136: 27-11-2020 | B136: 25059.6 | C136: 6114.1 | D136: 172.3 | E136: 230.6 | I136: 231.7 | J136: 147.2 | K136: -55.9 | L136: -8.6 | P136: 46235.2 | Q136: 46363.1 | S136: 37081.01 | T136: 37449.3 | V136: =SUM(I133:I152) -> 701.8
A137: 04-12-2020 | B137: 25043.3 | C137: 6195 | D137: 134.3 | E137: 228.1 | I137: -23.3 | J137: 91.4 | K137: -39.1 | L137: -2.4 | P137: 48847.2 | Q137: 48487.9 | S137: 37334.06 | T137: 37571.4 | V137: DIBS Flow
A138: 11-12-2020 | B138: 25317.1 | C138: 6248.6 | D138: 138.7 | E138: 223.6 | I138: 41 | J138: 99 | K138: 4 | L138: -4.5 | P138: 48420.3 | Q138: 48515.4 | S138: 38182.92 | T138: 38358.69 | V138: =SUM(J133:J152) -> 4428.6
A139: 18-12-2020 | B139: 26540.1 | C139: 8028.3 | D139: 1733.1 | E139: 219 | I139: 244 | J139: 1661.8 | K139: 1591.5 | L139: -4.6 | P139: 49628.3 | Q139: 48717.8 | S139: 38115.65 | T139: 38207.08 | V139: Repo Flow
A140: 25-12-2020 | B140: 27275 | C140: 8270.8 | D140: 1717.6 | E140: 224 | I140: -18.8 | J140: 106.7 | K140: -30.9 | L140: 5 | P140: 49594.7 | Q140: 48726.9 | S140: 38306.63 | T140: 38397.31 | V140: =SUM(K133:K152) -> 1732.2
A141: 01-01-2021 | B141: 29168.1 | C141: 8597.5 | D141: 1850.3 | E141: 224.8 | I141: 90.7 | J141: 35.1 | K141: 94.7 | L141: 0.8 | P141: 49910.2 | Q141: 48640.7 | S141: 38459.17 | T141: 38388.19 | V141: OSBA Flow
A142: 08-01-2021 | B142: 30874.4 | C142: 9159 | D142: 1817.2 | E142: 222.3 | I142: 287.7 | J142: 491.1 | K142: -44.5 | L142: -2.5 | P142: 49897.9 | Q142: 48821.7 | S142: 38445.64 | T142: 38397.69 | V142: =SUM(L133:L152) -> 60.8
A143: 15-01-2021 | B143: 30534.5 | C143: 8981.2 | D143: 1886 | E143: 222.5 | I143: 31.4 | J143: -17.7 | K143: 93.8 | L143: 0.2 | P143: 49481 | Q143: 48932.7 | S143: 38956.51 | T143: 38746.47 | V143: TR Eurobond Flow
A144: 22-01-2021 | B144: 30429.7 | C144: 9062 | D144: 1875.3 | E144: 248.9 | I144: -117.7 | J144: 33.4 | K144: -10.8 | L144: 26.3 | P144: 49407.9 | Q144: 48758.9 | S144: 38960.06 | T144: 38720.16 | V144: =Q152-Q133 -> 3645
A145: 29-01-2021 | B145: 28920 | C145: 9523.2 | D145: 1875.6 | E145: 239.1 | I145: -493.7 | J145: 418.7 | K145: 4.5 | L145: -9.8 | P145: 52961.3 | Q145: 51896.8 | S145: 39583.37 | T145: 39277.1 | V145: Şirket Eurobond Flow
A146: 05-02-2021 | B146: 30814.9 | C146: 9961.5 | D146: 1923.7 | E146: 272.9 | I146: -183.2 | J146: 140.5 | K146: 21.6 | L146: 33.8 | P146: 53500 | Q146: 52029.5 | S146: 40359.61 | T146: 39883.7 | V146: =T152-T133 -> 1406.19
A147: 12-02-2021 | B147: 31019.6 | C147: 10249.9 | D147: 1964.6 | E147: 281.4 | I147: -62.3 | J147: 128.2 | K147: 15.7 | L147: 8.5 | P147: 53750.8 | Q147: 52320.7 | S147: 39821.75 | T147: 39228.5 | V147: Swap
A148: 19-02-2021 | B148: 31378 | C148: 10474.5 | D148: 1969.2 | E148: 289.2 | I148: -122.8 | J148: 194.5 | K148: -4.6 | L148: 7.8 | P148: 53468.3 | Q148: 52213.8 | S148: 39952.43 | T148: 39278.9 | V148: =Swap!G12 -> 14903
A149: 26-02-2021 | B149: 28563.1 | C149: 10254.2 | D149: 1962 | E149: 267.6 | I149: -117.6 | J149: 83.2 | K149: 17.4 | L149: -21.6 | P149: 52314.5 | Q149: 52057.2 | S149: 39698.58 | T149: 39160.2 | V149: Total Giriş-
A150: 05-03-2021 | B150: 28969.9 | C150: 9853.1 | D150: 1932.5 | E150: 263.5 | I150: -10.1 | J150: 49.8 | K150: 22.9 | L150: -4.2 | P150: 51513.5 | Q150: 51868.2 | S150: 39648.66 | T150: 39163.8 | V150: =SUM(V135:V148) -> 26877.59
A151: 12-03-2021 | B151: 29154 | C151: 9604.2 | D151: 1904.5 | E151: 282.3 | I151: -117.6 | J151: -126.4 | K151: 3.1 | L151: 18.9 | P151: 51302.3 | Q151: 51472.4 | S151: 39142.54 | T151: 38731.3
A152: 19-03-2021 | B152: 28946.4 | C152: 9956.7 | D152: 1858 | E152: 282.1 | I152: 60.4 | J152: 427.2 | K152: -43.3 | L152: -0.2 | P152: 50127 | Q152: 50047 | S152: 39281.78 | T152: 38797.5
A153: 44281 | B153: 23782.3 | C153: 7670.5 | D153: 1724.1 | E153: 265.3 | I153: -813.9 | J153: -1104.8 | K153: -11.7 | L153: -16.8 | P153: 46628.5 | Q153: 49460.8 | S153: 38186.32 | T153: 38653.8
A154: 44288 | B154: 23405.5 | C154: 7370.4 | D154: 1718.6 | E154: 261.2 | I154: -364.4 | J154: -140.4 | K154: 13.1 | L154: -4.1 | P154: 46148.2 | Q154: 48481.4 | S154: 39516.66 | T154: 38814.4
A155: 44295 | B155: 22776.3 | C155: 7464 | D155: 1724.2 | E155: 264.7 | I155: -46 | J155: 77.9 | K155: -6 | L155: 3.4 | P155: 46116.6 | Q155: 48143.1 | S155: 38533.3 | T155: 38755.2
A156: 44302 | B156: 23176.5 | C156: 7786.5 | D156: 1921.1 | E156: 282.7 | I156: 0 | J156: 164.9 | K156: 172 | L156: 18 | P156: 46686.5 | Q156: 47959.1 | S156: 38992.42 | T156: 38912.5
...

Sheet DTH
A1: Her Perşembe | B1: date | C1: bireylerin döviz hesapları | D1: tuzellerin döviz hesapları | E1: birey - tüzel spreadi | F1: Birey / Tüzel Rasyosu | G1: Toplam | H1: birey | I1: 13w Birey kümülatif | J1: tuzel | K1: 13w Tüzel kümülatif | L1: Toplam | M1: 13w toplam kümülatif
A2: EVDS -> YABANCI PARA MEVDUAT | B2: 41263 | C2: 67883 | D2: 43637 | G2: =C2+D2 -> 111520
B3: 41264 | C3: 68103 | D3: 44074 | E3: =C3-D3 -> 24029 | F3: =C3/D3 -> 1.5451967 | G3: =C3+D3 -> 112177 | H3: =C3-C2 -> 220 | J3: =D3-D2 -> 437 | L3: =H3+J3 -> 657
B4: 41271 | C4: 77793.038 | D4: 45253.757 | E4: =C4-D4 -> 32539.281 | F4: =C4/D4 -> 1.7190404 | G4: =C4+D4 -> 123046.79 | H4: =C4-C3 -> 9690.0378 | J4: =D4-D3 -> 1179.7567 | L4: =H4+J4 -> 10869.794
B5: 41278 | C5: 77858.058 | D5: 43850.298 | E5: =C5-D5 -> 34007.761 | F5: =C5/D5 -> 1.7755423 | G5: =C5+D5 -> 121708.36 | H5: =C5-C4 -> 65.020601 | J5: =D5-D4 -> -1403.4588 | L5: =H5+J5 -> -1338.4382
B6: 41285 | C6: 78964.258 | D6: 46448.785 | E6: =C6-D6 -> 32515.473 | F6: =C6/D6 -> 1.7000285 | G6: =C6+D6 -> 125413.04 | H6: =C6-C5 -> 1106.1995 | J6: =D6-D5 -> 2598.487 | L6: =H6+J6 -> 3704.6865
B7: 41292 | C7: 79634.204 | D7: 46944.187 | E7: =C7-D7 -> 32690.016 | F7: =C7/D7 -> 1.6963592 | G7: =C7+D7 -> 126578.39 | H7: =C7-C6 -> 669.94582 | J7: =D7-D6 -> 495.4026 | L7: =H7+J7 -> 1165.3484
B8: 41299 | C8: 79853.274 | D8: 47154.437 | E8: =C8-D8 -> 32698.837 | F8: =C8/D8 -> 1.6934413 | G8: =C8+D8 -> 127007.71 | H8: =C8-C7 -> 219.07024 | J8: =D8-D7 -> 210.2498 | L8: =H8+J8 -> 429.32004
B9: 41306 | C9: 80655.624 | D9: 46678.861 | E9: =C9-D9 -> 33976.763 | F9: =C9/D9 -> 1.7278833 | G9: =C9+D9 -> 127334.48 | H9: =C9-C8 -> 802.34972 | J9: =D9-D8 -> -475.57671 | L9: =H9+J9 -> 326.773
B10: 41313 | C10: 80351.913 | D10: 46014.276 | E10: =C10-D10 -> 34337.638 | F10: =C10/D10 -> 1.7462388 | G10: =C10+D10 -> 126366.19 | H10: =C10-C9 -> -303.71043 | J10: =D10-D9 -> -664.58496 | L10: =H10+J10 -> -968.29539
B11: 41320 | C11: 80156.365 | D11: 44957.208 | E11: =C11-D11 -> 35199.158 | F11: =C11/D11 -> 1.782948 | G11: =C11+D11 -> 125113.57 | H11: =C11-C10 -> -195.54805 | J11: =D11-D10 -> -1057.068 | L11: =H11+J11 -> -1252.6161
B12: 41327 | C12: 79307.744 | D12: 44005.48 | E12: =C12-D12 -> 35302.264 | F12: =C12/D12 -> 1.8022243 | G12: =C12+D12 -> 123313.22 | H12: =C12-C11 -> -848.62087 | J12: =D12-D11 -> -951.72766 | L12: =H12+J12 -> -1800.3485
B13: 41334 | C13: 78598.018 | D13: 43992.928 | E13: =C13-D13 -> 34605.09 | F13: =C13/D13 -> 1.7866058 | G13: =C13+D13 -> 122590.95 | H13: =C13-C12 -> -709.72626 | J13: =D13-D12 -> -12.552379 | L13: =H13+J13 -> -722.27864
B14: 41341 | C14: 78504.977 | D14: 44519.366 | E14: =C14-D14 -> 33985.611 | F14: =C14/D14 -> 1.7633894 | G14: =C14+D14 -> 123024.34 | H14: =C14-C13 -> -93.040993 | J14: =D14-D13 -> 526.43833 | L14: =H14+J14 -> 433.39734
B15: 41348 | C15: 78093.298 | D15: 44954.751 | E15: =C15-D15 -> 33138.548 | F15: =C15/D15 -> 1.7371534 | G15: =C15+D15 -> 123048.05 | H15: =C15-C14 -> -411.67851 | I15: =SUM(H3:H15) -> 10210.298 | J15: =D15-D14 -> 435.38504 | K15: =SUM(J3:J15) -> 1317.7509 | L15: =H15+J15 -> 23.706524 | M15: =SUM(L3:L15) -> 11528.049
B16: 41355 | C16: 77324.736 | D16: 44966.802 | E16: =C16-D16 -> 32357.934 | F16: =C16/D16 -> 1.7195961 | G16: =C16+D16 -> 122291.54 | H16: =C16-C15 -> -768.56225 | I16: =SUM(H4:H16) -> 9221.7362 | J16: =D16-D15 -> 12.051466 | K16: =SUM(J4:J16) -> 892.80239 | L16: =H16+J16 -> -756.51078 | M16: =SUM(L4:L16) -> 10114.539
B17: 41362 | C17: 77133.158 | D17: 45462.069 | E17: =C17-D17 -> 31671.09 | F17: =C17/D17 -> 1.6966487 | G17: =C17+D17 -> 122595.23 | H17: =C17-C16 -> -191.57781 | I17: =SUM(H5:H17) -> -659.87935 | J17: =D17-D16 -> 495.26644 | K17: =SUM(J5:J17) -> 208.31216 | L17: =H17+J17 -> 303.68863 | M17: =SUM(L5:L17) -> -451.56719
B18: 41369 | C18: 77818.122 | D18: 46570.177 | E18: =C18-D18 -> 31247.945 | F18: =C18/D18 -> 1.6709862 | G18: =C18+D18 -> 124388.3 | H18: =C18-C17 -> 684.96315 | I18: =SUM(H6:H18) -> -39.936799 | J18: =D18-D17 -> 1108.1077 | K18: =SUM(J6:J18) -> 2719.8787 | L18: =H18+J18 -> 1793.0709 | M18: =SUM(L6:L18) -> 2679.9419
B19: 41376 | C19: 78921.064 | D19: 47632.586 | E19: =C19-D19 -> 31288.479 | F19: =C19/D19 -> 1.6568713 | G19: =C19+D19 -> 126553.65 | H19: =C19-C18 -> 1102.9427 | I19: =SUM(H7:H19) -> -43.19351 | J19: =D19-D18 -> 1062.4091 | K19: =SUM(J7:J19) -> 1183.8008 | L19: =H19+J19 -> 2165.3518 | M19: =SUM(L7:L19) -> 1140.6073
B20: 41383 | C20: 78917.109 | D20: 47705.429 | E20: =C20-D20 -> 31211.679 | F20: =C20/D20 -> 1.6542584 | G20: =C20+D20 -> 126622.54 | H20: =C20-C19 -> -3.955445 | I20: =SUM(H8:H20) -> -717.09477 | J20: =D20-D19 -> 72.843858 | K20: =SUM(J8:J20) -> 761.24202 | L20: =H20+J20 -> 68.888413 | M20: =SUM(L8:L20) -> 44.147242
B21: 41390 | C21: 79235.552 | D21: 47773.344 | E21: =C21-D21 -> 31462.208 | F21: =C21/D21 -> 1.6585725 | G21: =C21+D21 -> 127008.9 | H21: =C21-C20 -> 318.44294 | I21: =SUM(H9:H21) -> -617.72207 | J21: =D21-D20 -> 67.914079 | K21: =SUM(J9:J21) -> 618.90629 | L21: =H21+J21 -> 386.35702 | M21: =SUM(L9:L21) -> 1.184223
B22: 41397 | C22: 79642.018 | D22: 46979.764 | E22: =C22-D22 -> 32662.254 | F22: =C22/D22 -> 1.6952409 | G22: =C22+D22 -> 126621.78 | H22: =C22-C21 -> 406.46595 | I22: =SUM(H10:H22) -> -1013.6058 | J22: =D22-D21 -> -793.57971 | K22: =SUM(J10:J22) -> 300.9033 | L22: =H22+J22 -> -387.11376 | M22: =SUM(L10:L22) -> -712.70254
B23: 41404 | C23: 79126.906 | D23: 46145.09 | E23: =C23-D23 -> 32981.816 | F23: =C23/D23 -> 1.7147416 | G23: =C23+D23 -> 125272 | H23: =C23-C22 -> -515.11157 | I23: =SUM(H11:H23) -> -1225.007 | J23: =D23-D22 -> -834.67339 | K23: =SUM(J11:J23) -> 130.81487 | L23: =H23+J23 -> -1349.785 | M23: =SUM(L11:L23) -> -1094.1921
B24: 41411 | C24: 77559.294 | D24: 44642.075 | E24: =C24-D24 -> 32917.219 | F24: =C24/D24 -> 1.7373586 | G24: =C24+D24 -> 122201.37 | H24: =C24-C23 -> -1567.6125 | I24: =SUM(H12:H24) -> -2597.0714 | J24: =D24-D23 -> -1503.0159 | K24: =SUM(J12:J24) -> -315.13308 | L24: =H24+J24 -> -3070.6285 | M24: =SUM(L12:L24) -> -2912.2045
B25: 41418 | C25: 76570.593 | D25: 45762.26 | E25: =C25-D25 -> 30808.333 | F25: =C25/D25 -> 1.6732258 | G25: =C25+D25 -> 122332.85 | H25: =C25-C24 -> -988.70021 | I25: =SUM(H13:H25) -> -2737.1508 | J25: =D25-D24 -> 1120.1857 | K25: =SUM(J13:J25) -> 1756.7802 | L25: =H25+J25 -> 131.48544 | M25: =SUM(L13:L25) -> -980.37055
B26: 41425 | C26: 75979.828 | D26: 46705.707 | E26: =C26-D26 -> 29274.122 | F26: =C26/D26 -> 1.6267783 | G26: =C26+D26 -> 122685.53 | H26: =C26-C25 -> -590.76504 | I26: =SUM(H14:H26) -> -2618.1896 | J26: =D26-D25 -> 943.44639 | K26: =SUM(J14:J26) -> 2712.779 | L26: =H26+J26 -> 352.68136 | M26: =SUM(L14:L26) -> 94.58945
... B543: 45044 | C543: 111763.42 | D543: 75005.8 | E543: =C543-D543 -> 36757.62 | F543: =C543/D543 -> 1.4900637 | G543: =C543+D543 -> 186769.22 | H543: =C543-C542 -> -354.62 | I543: =SUM(H531:H543) -> -5521.39 | J543: =D543-D542 -> -1676.84 | K543: =SUM(J531:J543) -> -3758.73 | L543: =H543+J543 -> -2031.46 | M543: =SUM(L531:L543) -> -9280.12
B544: 45051 | C544: 112317.59 | D544: 76716.18 | E544: =C544-D544 -> 35601.41 | F544: =C544/D544 -> 1.4640665 | G544: =C544+D544 -> 189033.77 | H544: =C544-C543 -> 554.17 | I544: =SUM(H532:H544) -> -3665.94 | J544: =D544-D543 -> 1710.38 | K544: =SUM(J532:J544) -> -2778.17 | L544: =H544+J544 -> 2264.55 | M544: =SUM(L532:L544) -> -6444.11 | P544: DTH hesaplarında ilginç bir ayrışma var. Seçimden ve KKM'nin ölümünün açıklandığından bu yana Bireyler DTH'larını hiç artırmazken kurumlar son hızda DTH hesaplarını dolduruyorlar. Tıpkı KKM açıklandığında duruma uyanamayan bireylerin DTHlarını azaltmayıp tüzellerin son hızda azaltması gibi. Bireyler mevcut denklemi geç anlıyor gibi.
B545: 45058 | C545: 112016.9 | D545: 73625.45 | E545: =C545-D545 -> 38391.45 | F545: =C545/D545 -> 1.5214427 | G545: =C545+D545 -> 185642.35 | H545: =C545-C544 -> -300.69 | I545: =SUM(H533:H545) -> -2360.1 | J545: =D545-D544 -> -3090.73 | K545: =SUM(J533:J545) -> -5525.68 | L545: =H545+J545 -> -3391.42 | M545: =SUM(L533:L545) -> -7885.78
B546: 45065 | C546: 109658.29 | D546: 73346.76 | E546: =C546-D546 -> 36311.53 | F546: =C546/D546 -> 1.4950666 | G546: =C546+D546 -> 183005.05 | H546: =C546-C545 -> -2358.61 | I546: =SUM(H534:H546) -> -3173.19 | J546: =D546-D545 -> -278.69 | K546: =SUM(J534:J546) -> -4342.28 | L546: =H546+J546 -> -2637.3 | M546: =SUM(L534:L546) -> -7515.47
B547: 45072 | C547: 105747.64 | D547: 70256.17 | E547: =C547-D547 -> 35491.47 | F547: =C547/D547 -> 1.5051723 | G547: =C547+D547 -> 176003.81 | H547: =C547-C546 -> -3910.65 | I547: =SUM(H535:H547) -> -4948.92 | J547: =D547-D546 -> -3090.59 | K547: =SUM(J535:J547) -> -4885.54 | L547: =H547+J547 -> -7001.24 | M547: =SUM(L535:L547) -> -9834.46
B548: 45079 | C548: 105451.38 | D548: 70011.2 | E548: =C548-D548 -> 35440.18 | F548: =C548/D548 -> 1.5062073 | G548: =C548+D548 -> 175462.58 | H548: =C548-C547 -> -296.26 | I548: =SUM(H536:H548) -> -5744.69 | J548: =D548-D547 -> -244.97 | K548: =SUM(J536:J548) -> -5220.59 | L548: =H548+J548 -> -541.23 | M548: =SUM(L536:L548) -> -10965.28
B549: 45086 | C549: 104970.77 | D549: 68703.48 | E549: =C549-D549 -> 36267.29 | F549: =C549/D549 -> 1.5278814 | G549: =C549+D549 -> 173674.25 | H549: =C549-C548 -> -480.61 | I549: =SUM(H537:H549) -> -6116.67 | J549: =D549-D548 -> -1307.72 | K549: =SUM(J537:J549) -> -7767.34 | L549: =H549+J549 -> -1788.33 | M549: =SUM(L537:L549) -> -13884.01
B550: 45093 | C550: 104939 | D550: 71397 | E550: =C550-D550 -> 33542 | F550: =C550/D550 -> 1.4697956 | G550: =C550+D550 -> 176336 | H550: =C550-C549 -> -31.77 | I550: =SUM(H538:H550) -> -6255.94 | J550: =D550-D549 -> 2693.52 | K550: =SUM(J538:J550) -> -3850.17 | L550: =H550+J550 -> 2661.75 | M550: =SUM(L538:L550) -> -10106.11
B551: 45100 | C551: 101947 | D551: 66004 | E551: =C551-D551 -> 35943 | F551: =C551/D551 -> 1.5445579 | G551: =C551+D551 -> 167951 | H551: =C551-C550 -> -2992 | I551: =SUM(H539:H551) -> -9563.54 | J551: =D551-D550 -> -5393 | K551: =SUM(J539:J551) -> -8975.67 | L551: =H551+J551 -> -8385 | M551: =SUM(L539:L551) -> -18539.21
B552: 45107 | C552: 102600 | D552: 65707 | E552: =C552-D552 -> 36893 | F552: =C552/D552 -> 1.5614775 | G552: =C552+D552 -> 168307 | H552: =C552-C551 -> 653 | I552: =SUM(H540:H552) -> -8143.91 | J552: =D552-D551 -> -297 | K552: =SUM(J540:J552) -> -7232.67 | L552: =H552+J552 -> 356 | M552: =SUM(L540:L552) -> -15376.58
B553: 45114 | C553: 102632 | D553: 65997 | E553: =C553-D553 -> 36635 | F553: =C553/D553 -> 1.555101 | G553: =C553+D553 -> 168629 | H553: =C553-C552 -> 32 | I553: =SUM(H541:H553) -> -9358.25 | J553: =D553-D552 -> 290 | K553: =SUM(J541:J553) -> -9659.99 | L553: =H553+J553 -> 322 | M553: =SUM(L541:L553) -> -19018.24
B554: 45121 | C554: 103660 | D554: 67467 | E554: =C554-D554 -> 36193 | F554: =C554/D554 -> 1.5364549 | G554: =C554+D554 -> 171127 | H554: =C554-C553 -> 1028 | I554: =SUM(H542:H554) -> -8421.14 | J554: =D554-D553 -> 1470 | K554: =SUM(J542:J554) -> -8357.25 | L554: =H554+J554 -> 2498 | M554: =SUM(L542:L554) -> -16778.39
B555: 45128 | C555: 103687 | D555: 67129 | E555: =C555-D555 -> 36558 | F555: =C555/D555 -> 1.5445932 | G555: =C555+D555 -> 170816 | H555: =C555-C554 -> 27 | I555: =SUM(H543:H555) -> -8431.04 | J555: =D555-D554 -> -338 | K555: =SUM(J543:J555) -> -9553.64 | L555: =H555+J555 -> -311 | M555: =SUM(L543:L555) -> -17984.68
B556: 45135 | C556: 104543 | D556: 66999 | E556: =C556-D556 -> 37544 | F556: =C556/D556 -> 1.5603666 | G556: =C556+D556 -> 171542 | H556: =C556-C555 -> 856 | I556: =SUM(H544:H556) -> -7220.42 | J556: =D556-D555 -> -130 | K556: =SUM(J544:J556) -> -8006.8 | L556: =H556+J556 -> 726 | M556: =SUM(L544:L556) -> -15227.22
...

Sheet Menkul Kıymet - Güncel
A1: Her Perşembe | C1: Hisse Senedi - Flow | E1: DIBS - Flow | F1: Hisse fark | G1: DIBS fark | H1: 4 week cor | I1: 13 week cor | J1: Total Flow | K1: Toplam Kümülatif-2023 | O1: 13w Sum Hisse Flow | P1: 13w Sum tAHVİL Flow | Q1: 13w hisse flow - dibs flow
A2: TCMB MENK. İST | B2: 11-09-2020 | C2: -30.24 | E2: -10.58 | J2: =C2+E2 -> -40.82
B3: 18-09-2020 | C3: 2.57 | E3: -90.42 | F3: =C3-C2 -> 32.81 | G3: =E3-E2 -> -79.84 | J3: =C3+E3 -> -87.85
B4: 25-09-2020 | C4: -101.89 | E4: 1.7 | F4: =C4-C3 -> -104.46 | G4: =E4-E3 -> 92.12 | J4: =C4+E4 -> -100.19
B5: 02-10-2020 | C5: 131.22 | E5: 407.2 | F5: =C5-C4 -> 233.11 | G5: =E5-E4 -> 405.5 | H5: =CORREL(C2:C5,E2:E5) -> 0.81257493 | J5: =C5+E5 -> 538.42
B6: 09-10-2020 | C6: -91.33 | E6: -174.52 | F6: =C6-C5 -> -222.55 | G6: =E6-E5 -> -581.72 | H6: =CORREL(C3:C6,E3:E6) -> 0.85063951 | J6: =C6+E6 -> -265.85
B7: 16-10-2020 | C7: -28.37 | E7: -38.03 | F7: =C7-C6 -> 62.96 | G7: =E7-E6 -> 136.49 | H7: =CORREL(C4:C7,E4:E7) -> 0.92477044 | J7: =C7+E7 -> -66.4
B8: 23-10-2020 | C8: -10.82 | E8: 20.9 | F8: =C8-C7 -> 17.55 | G8: =E8-E7 -> 58.93 | H8: =CORREL(C5:C8,E5:E8) -> 0.99862015 | J8: =C8+E8 -> 10.08
B9: 30-10-2020 | C9: -116.63 | E9: -32.74 | F9: =C9-C8 -> -105.81 | G9: =E9-E8 -> -53.64 | H9: =CORREL(C6:C9,E6:E9) -> 0.53638465 | J9: =C9+E9 -> -149.37
B10: 06-11-2020 | C10: -21.99 | E10: -17.34 | F10: =C10-C9 -> 94.64 | G10: =E10-E9 -> 15.4 | H10: =CORREL(C7:C10,E7:E10) -> 0.53128496 | J10: =C10+E10 -> -39.33
B11: 13-11-2020 | C11: 614.4 | E11: 211.09 | F11: =C11-C10 -> 636.39 | G11: =E11-E10 -> 228.43 | H11: =CORREL(C8:C11,E8:E11) -> 0.9921364 | J11: =C11+E11 -> 825.49
B12: 20-11-2020 | C12: 389.64 | E12: 201.76 | F12: =C12-C11 -> -224.76 | G12: =E12-E11 -> -9.33 | H12: =CORREL(C9:C12,E9:E12) -> 0.96874449 | J12: =C12+E12 -> 591.4
B13: 27-11-2020 | C13: 231.71 | E13: 194.51 | F13: =C13-C12 -> -157.93 | G13: =E13-E12 -> -7.25 | H13: =CORREL(C10:C13,E10:E13) -> 0.84466666 | J13: =C13+E13 -> 426.22
B14: 04-12-2020 | C14: -23.27 | E14: 133.48 | F14: =C14-C13 -> -254.98 | G14: =E14-E13 -> -61.03 | H14: =CORREL(C11:C14,E11:E14) -> 0.90858674 | I14: =CORREL(C2:C14,E2:E14) -> 0.64646017 | J14: =C14+E14 -> 110.21 | O14: =SUM(C2:C14) -> 945 | P14: =SUM(E2:E14) -> 807.01 | Q14: =O14-P14 -> 137.99
B15: 11-12-2020 | C15: 40.97 | E15: 103.79 | F15: =C15-C14 -> 64.24 | G15: =E15-E14 -> -29.69 | H15: =CORREL(C12:C15,E12:E15) -> 0.88190438 | I15: =CORREL(C3:C15,E3:E15) -> 0.63394776 | J15: =C15+E15 -> 144.76 | O15: =SUM(C3:C15) -> 1016.21 | P15: =SUM(E3:E15) -> 921.38 | Q15: =O15-P15 -> 94.83
B16: 18-12-2020 | C16: 244.04 | E16: 44.88 | F16: =C16-C15 -> 203.07 | G16: =E16-E15 -> -58.91 | H16: =CORREL(C13:C16,E13:E16) -> -0.064804327 | I16: =CORREL(C4:C16,E4:E16) -> 0.60625454 | J16: =C16+E16 -> 288.92 | O16: =SUM(C4:C16) -> 1257.68 | P16: =SUM(E4:E16) -> 1056.68 | Q16: =O16-P16 -> 201
B17: 25-12-2020 | C17: -18.79 | E17: 159.25 | F17: =C17-C16 -> -262.83 | G17: =E17-E16 -> 114.37 | H17: =CORREL(C14:C17,E14:E17) -> -0.95488618 | I17: =CORREL(C5:C17,E5:E17) -> 0.55558158 | J17: =C17+E17 -> 140.46 | O17: =SUM(C5:C17) -> 1340.78 | P17: =SUM(E5:E17) -> 1214.23 | Q17: =O17-P17 -> 126.55
B18: 01-01-2021 | C18: 90.68 | E18: -85.97 | F18: =C18-C17 -> 109.47 | G18: =E18-E17 -> -245.22 | H18: =CORREL(C15:C18,E15:E18) -> -0.43324732 | I18: =CORREL(C6:C18,E6:E18) -> 0.64862394 | J18: =C18+E18 -> 4.71 | O18: =SUM(C6:C18) -> 1300.24 | P18: =SUM(E6:E18) -> 721.06 | Q18: =O18-P18 -> 579.18
B19: 08-01-2021 | C19: 287.71 | E19: 634.85 | F19: =C19-C18 -> 197.03 | G19: =E19-E18 -> 720.82 | H19: =CORREL(C16:C19,E16:E19) -> 0.51988396 | I19: =CORREL(C7:C19,E7:E19) -> 0.52122473 | J19: =C19+E19 -> 922.56 | O19: =SUM(C7:C19) -> 1679.28 | P19: =SUM(E7:E19) -> 1530.43 | Q19: =O19-P19 -> 148.85
B20: 15-01-2021 | C20: 31.41 | E20: -2.57 | F20: =C20-C19 -> -256.3 | G20: =E20-E19 -> -637.42 | H20: =CORREL(C17:C20,E17:E20) -> 0.79207421 | I20: =CORREL(C8:C20,E8:E20) -> 0.50711147 | J20: =C20+E20 -> 28.84 | O20: =SUM(C8:C20) -> 1739.06 | P20: =SUM(E8:E20) -> 1565.89 | Q20: =O20-P20 -> 173.17
B21: 22-01-2021 | C21: -117.71 | E21: 28.6 | F21: =C21-C20 -> -149.12 | G21: =E21-E20 -> 31.17 | H21: =CORREL(C18:C21,E18:E21) -> 0.7766421 | I21: =CORREL(C9:C21,E9:E21) -> 0.50737805 | J21: =C21+E21 -> -89.11 | O21: =SUM(C9:C21) -> 1632.17 | P21: =SUM(E9:E21) -> 1573.59 | Q21: =O21-P21 -> 58.58
B22: 29-01-2021 | C22: -493.75 | E22: 413.98 | F22: =C22-C21 -> -376.04 | G22: =E22-E21 -> 385.38 | H22: =CORREL(C19:C22,E19:E22) -> 0.1762428 | I22: =CORREL(C10:C22,E10:E22) -> 0.05565317 | J22: =C22+E22 -> -79.77 | O22: =SUM(C10:C22) -> 1255.05 | P22: =SUM(E10:E22) -> 2020.31 | Q22: =O22-P22 -> -765.26
B23: 05-02-2021 | C23: -183.22 | E23: 169.96 | F23: =C23-C22 -> 310.53 | G23: =E23-E22 -> -244.02 | H23: =CORREL(C20:C23,E20:E23) -> -0.9741298 | I23: =CORREL(C11:C23,E11:E23) -> 0.020200614 | J23: =C23+E23 -> -13.26 | O23: =SUM(C11:C23) -> 1093.82 | P23: =SUM(E11:E23) -> 2207.61 | Q23: =O23-P23 -> -1113.79
B24: 12-02-2021 | C24: -62.34 | E24: 83.52 | F24: =C24-C23 -> 120.88 | G24: =E24-E23 -> -86.44 | H24: =CORREL(C21:C24,E21:E24) -> -0.96481707 | I24: =CORREL(C12:C24,E12:E24) -> -0.0063254168 | J24: =C24+E24 -> 21.18 | O24: =SUM(C12:C24) -> 417.08 | P24: =SUM(E12:E24) -> 2080.04 | Q24: =O24-P24 -> -1662.96
B25: 19-02-2021 | C25: -122.76 | E25: 169.58 | F25: =C25-C24 -> -60.42 | G25: =E25-E24 -> 86.06 | H25: =CORREL(C22:C25,E22:E25) -> -0.98986252 | I25: =CORREL(C13:C25,E13:E25) -> -0.045062905 | J25: =C25+E25 -> 46.82 | O25: =SUM(C13:C25) -> -95.32 | P25: =SUM(E13:E25) -> 2047.86 | Q25: =O25-P25 -> -2143.18
... B92: 03-06-2022 | C92: 130.13 | E92: -1.63 | F92: =C92-C91 -> 170.99 | G92: =E92-E91 -> 53.36 | H92: =CORREL(C89:C92,E89:E92) -> 0.79809295 | I92: =CORREL(C80:C92,E80:E92) -> 0.69925153 | J92: =C92+E92 -> 128.5 | O92: =SUM(C80:C92) -> -1873.34 | P92: =SUM(E80:E92) -> -683.82 | Q92: =O92-P92 -> -1189.52
B93: 10-06-2022 | C93: -316.07 | E93: -85.02 | F93: =C93-C92 -> -446.2 | G93: =E93-E92 -> -83.39 | H93: =CORREL(C90:C93,E90:E93) -> 0.75486409 | I93: =CORREL(C81:C93,E81:E93) -> 0.69509647 | J93: =C93+E93 -> -401.09 | N93: Son 1 Senede Total Flow | O93: =SUM(C81:C93) -> -1899.98 | P93: =SUM(E81:E93) -> -647.89 | Q93: =O93-P93 -> -1252.09
B94: 17-06-2022 | C94: -192.82 | E94: -144.66 | F94: =C94-C93 -> 123.25 | G94: =E94-E93 -> -59.64 | H94: =CORREL(C91:C94,E91:E94) -> 0.77473065 | I94: =CORREL(C82:C94,E82:E94) -> 0.69314323 | J94: =C94+E94 -> -337.48 | N94: =J93+J94 -> -738.57 | O94: =SUM(C82:C94) -> -1895.7 | P94: =SUM(E82:E94) -> -776.66 | Q94: =O94-P94 -> -1119.04
B95: 24-06-2022 | C95: -98.41 | E95: -57.7 | F95: =C95-C94 -> 94.41 | G95: =E95-E94 -> 86.96 | H95: =CORREL(C92:C95,E92:E95) -> 0.76536367 | I95: =CORREL(C83:C95,E83:E95) -> 0.73474631 | J95: =C95+E95 -> -156.11 | N95: =N94+J95 -> -894.68 | O95: =SUM(C83:C95) -> -2012.9 | P95: =SUM(E83:E95) -> -729.55 | Q95: =O95-P95 -> -1283.35
B96: 01-07-2022 | C96: -59.74 | E96: 22.1 | F96: =C96-C95 -> 38.67 | G96: =E96-E95 -> 79.8 | H96: =CORREL(C93:C96,E93:E96) -> 0.6277995 | I96: =CORREL(C84:C96,E84:E96) -> 0.75419522 | J96: =C96+E96 -> -37.64 | N96: =N95+J96 -> -932.32 | O96: =SUM(C84:C96) -> -2082.79 | P96: =SUM(E84:E96) -> -811.2 | Q96: =O96-P96 -> -1271.59
B97: 08-07-2022 | C97: -62.2 | E97: -54.46 | F97: =C97-C96 -> -2.46 | G97: =E97-E96 -> -76.56 | H97: =CORREL(C94:C97,E94:E97) -> 0.89517436 | I97: =CORREL(C85:C97,E85:E97) -> 0.79737632 | J97: =C97+E97 -> -116.66 | N97: =N96+J97 -> -1048.98 | O97: =SUM(C85:C97) -> -2390.15 | P97: =SUM(E85:E97) -> -826.92 | Q97: =O97-P97 -> -1563.23
B98: 15-07-2022 | C98: -37.42 | E98: -41.94 | F98: =C98-C97 -> 24.78 | G98: =E98-E97 -> 12.52 | H98: =CORREL(C95:C98,E95:E98) -> 0.2857923 | I98: =CORREL(C86:C98,E86:E98) -> 0.7841903 | J98: =C98+E98 -> -79.36 | N98: =N97+J98 -> -1128.34 | O98: =SUM(C86:C98) -> -2454.44 | P98: =SUM(E86:E98) -> -905.62 | Q98: =O98-P98 -> -1548.82
B99: 22-07-2022 | C99: -76.55 | E99: -4.17 | F99: =C99-C98 -> -39.13 | G99: =E99-E98 -> 37.77 | H99: =CORREL(C96:C99,E96:E99) -> -0.39501836 | I99: =CORREL(C87:C99,E87:E99) -> 0.7811258 | J99: =C99+E99 -> -80.72 | N99: =N98+J99 -> -1209.06 | O99: =SUM(C87:C99) -> -2478.24 | P99: =SUM(E87:E99) -> -887.62 | Q99: =O99-P99 -> -1590.62
B100: 29-07-2022 | C100: -26.9 | E100: -21.11 | F100: =C100-C99 -> 49.65 | G100: =E100-E99 -> -16.94 | H100: =CORREL(C97:C100,E97:E100) -> -0.22020487 | I100: =CORREL(C88:C100,E88:E100) -> 0.78645969 | J100: =C100+E100 -> -48.01 | N100: =N99+J100 -> -1257.07 | O100: =SUM(C88:C100) -> -2395.12 | P100: =SUM(E88:E100) -> -884.8 | Q100: =O100-P100 -> -1510.32
B101: 05-08-2022 | C101: 88.02 | E101: 6.81 | F101: =C101-C100 -> 114.92 | G101: =E101-E100 -> 27.92 | H101: =CORREL(C98:C101,E98:E101) -> 0.50005019 | I101: =CORREL(C89:C101,E89:E101) -> 0.80105158 | J101: =C101+E101 -> 94.83 | N101: =N100+J101 -> -1162.24 | O101: =SUM(C89:C101) -> -2062.94 | P101: =SUM(E89:E101) -> -802.2 | Q101: =O101-P101 -> -1260.74
B102: 12-08-2022 | C102: 270.04 | E102: 2.52 | F102: =C102-C101 -> 182.02 | G102: =E102-E101 -> -4.29 | H102: =CORREL(C99:C102,E99:E102) -> 0.56146678 | I102: =CORREL(C90:C102,E90:E102) -> 0.58915624 | J102: =C102+E102 -> 272.56 | N102: =N101+J102 -> -889.68 | O102: =SUM(C90:C102) -> -1026.03 | P102: =SUM(E90:E102) -> -501.57 | Q102: =O102-P102 -> -524.46
B103: 19-08-2022 | C103: 366.2 | E103: -9.54 | F103: =C103-C102 -> 96.16 | G103: =E103-E102 -> -12.06 | H103: =CORREL(C100:C103,E100:E103) -> 0.30985429 | I103: =CORREL(C91:C103,E91:E103) -> 0.6300112 | J103: =C103+E103 -> 356.66 | N103: =N102+J103 -> -533.02 | O103: =SUM(C91:C103) -> -56.58 | P103: =SUM(E91:E103) -> -443.79 | Q103: =O103-P103 -> 387.21
B104: 26-08-2022 | C104: -32 | E104: -5.86 | F104: =C104-C103 -> -398.2 | G104: =E104-E103 -> 3.68 | H104: =CORREL(C101:C104,E101:E104) -> -0.24232091 | I104: =CORREL(C92:C104,E92:E104) -> 0.61248146 | J104: =C104+E104 -> -37.86 | N104: =N103+J104 -> -570.88 | O104: =SUM(C92:C104) -> -47.72 | P104: =SUM(E92:E104) -> -394.66 | Q104: =O104-P104 -> 346.94
B105: 02-09-2022 | C105: 97.95 | E105: -63.47 | F105: =C105-C104 -> 129.95 | G105: =E105-E104 -> -57.61 | H105: =CORREL(C102:C105,E102:E105) -> 0.28555532 | I105: =CORREL(C93:C105,E93:E105) -> 0.5444537 | J105: =C105+E105 -> 34.48 | N105: =N104+J105 -> -536.4 | O105: =SUM(C93:C105) -> -79.9 | P105: =SUM(E93:E105) -> -456.5 | Q105: =O105-P105 -> 376.6
B106: 09-09-2022 | C106: -13.48 | E106: -24.78 | F106: =C106-C105 -> -111.43 | G106: =E106-E105 -> 38.69 | H106: =CORREL(C103:C106,E103:E106) -> 0.11442132 | I106: =CORREL(C94:C106,E94:E106) -> 0.46072595 | J106: =C106+E106 -> -38.26 | N106: =N105+J106 -> -574.66 | O106: =SUM(C94:C106) -> 222.69 | P106: =SUM(E94:E106) -> -396.26 | Q106: =O106-P106 -> 618.95
...

Sheet Inflow - Outflow  - Stok
B1: Stok( 30.07.2021) | D1: 6 Kasım-19 Mart inFlow | H1: FLOW | AD1: 19 Mart Sonrası Kümülatif
A2: YABANCI | H2: 44281 | I2: 44288 | J2: 44295 | K2: 44302 | L2: 44308 | M2: 44316 | N2: 44323 | O2: 44330 | P2: 44337 | Q2: 44344 | R2: 44351 | S2: 44358 | T2: 44365 | U2: 44372 | V2: 44379 | W2: 44386 | X2: 44393 | Y2: 44400 | Z2: 44407 | AA2: 44414 | AB2: 44421
A3: Hisse Senedi | B3: ='Menkul Kıymet'!B172 -> 22047.5 | D3: ='Menkul Kıymet'!V136 -> 701.8 | H3: ='Menkul Kıymet'!I153 -> -813.9 | I3: ='Menkul Kıymet'!I154 -> -364.4 | J3: ='Menkul Kıymet'!I155 -> -46 | K3: ='Menkul Kıymet'!I156 -> 0 | L3: ='Menkul Kıymet'!I157 -> 104.5 | M3: ='Menkul Kıymet'!I158 -> 31.5 | N3: ='Menkul Kıymet'!I159 -> 87.7 | O3: ='Menkul Kıymet'!I160 -> 51.7 | P3: ='Menkul Kıymet'!I161 -> 51 | Q3: ='Menkul Kıymet'!I162 -> 6.8 | R3: ='Menkul Kıymet'!I163 -> -97.7 | S3: ='Menkul Kıymet'!I164 -> 33.5 | T3: ='Menkul Kıymet'!I165 -> -3.2 | U3: ='Menkul Kıymet'!I166 -> -3.4 | V3: ='Menkul Kıymet'!I167 -> -38.1 | W3: ='Menkul Kıymet'!I168 -> 54.2 | X3: ='Menkul Kıymet'!I169 -> -62 | Y3: ='Menkul Kıymet'!I170 -> 0 | Z3: ='Menkul Kıymet'!I171 -> -51.8 | AA3: ='Menkul Kıymet'!I172 -> 168 | AD3: =SUM(H3:AA3) -> -891.6
A4: DIBS | B4: ='Menkul Kıymet'!C172 -> 8570.7 | D4: ='Menkul Kıymet'!V138 -> 4428.6 | H4: ='Menkul Kıymet'!J153 -> -1104.8 | I4: ='Menkul Kıymet'!J154 -> -140.4 | J4: ='Menkul Kıymet'!J155 -> 77.9 | K4: ='Menkul Kıymet'!J156 -> 164.9 | L4: ='Menkul Kıymet'!J157 -> -252.6 | M4: ='Menkul Kıymet'!J158 -> 33 | N4: ='Menkul Kıymet'!J159 -> 23.7 | O4: ='Menkul Kıymet'!J160 -> 118.5 | P4: ='Menkul Kıymet'!J161 -> 174.8 | Q4: ='Menkul Kıymet'!J162 -> 69.2 | R4: ='Menkul Kıymet'!J163 -> -64.1 | S4: ='Menkul Kıymet'!J164 -> 80.3 | T4: ='Menkul Kıymet'!J165 -> -3.6 | U4: ='Menkul Kıymet'!J166 -> 172.5 | V4: ='Menkul Kıymet'!J167 -> 83 | W4: ='Menkul Kıymet'!J168 -> 5.9 | X4: ='Menkul Kıymet'!J169 -> 56.5 | Y4: ='Menkul Kıymet'!J170 -> 16.1 | Z4: ='Menkul Kıymet'!J171 -> 300.7 | AA4: ='Menkul Kıymet'!J172 -> 113.8 | AD4: =SUM(H4:AA4) -> -74.7
A5: Repo | B5: ='Menkul Kıymet'!D172 -> 1778.1 | D5: ='Menkul Kıymet'!V140 -> 1732.2 | H5: ='Menkul Kıymet'!K153 -> -11.7 | I5: ='Menkul Kıymet'!K154 -> 13.1 | J5: ='Menkul Kıymet'!K155 -> -6 | K5: ='Menkul Kıymet'!K156 -> 172 | L5: ='Menkul Kıymet'!K157 -> -323.8 | M5: ='Menkul Kıymet'!K158 -> 129.6 | N5: ='Menkul Kıymet'!K159 -> -12.4 | O5: ='Menkul Kıymet'!K160 -> 27.5 | P5: ='Menkul Kıymet'!K161 -> 47.8 | Q5: ='Menkul Kıymet'!K162 -> 267.7 | R5: ='Menkul Kıymet'!K163 -> -13 | S5: ='Menkul Kıymet'!K164 -> -112.1 | T5: ='Menkul Kıymet'!K165 -> -86 | U5: ='Menkul Kıymet'!K166 -> -36.8 | V5: ='Menkul Kıymet'!K167 -> 69.3 | W5: ='Menkul Kıymet'!K168 -> -59.8 | X5: ='Menkul Kıymet'!K169 -> -17.8 | Y5: ='Menkul Kıymet'!K170 -> 14.7 | Z5: ='Menkul Kıymet'!K171 -> 8.5 | AA5: ='Menkul Kıymet'!K172 -> -15.5 | AD5: =SUM(H5:AA5) -> 55.3
A6: OSBA | B6: ='Menkul Kıymet'!E172 -> 224.2 | D6: ='Menkul Kıymet'!V142 -> 60.8 | H6: ='Menkul Kıymet'!L153 -> -16.8 | I6: ='Menkul Kıymet'!L154 -> -4.1 | J6: ='Menkul Kıymet'!L155 -> 3.4 | K6: ='Menkul Kıymet'!L156 -> 18 | L6: ='Menkul Kıymet'!L157 -> -22.1 | M6: ='Menkul Kıymet'!L158 -> 6.5 | N6: ='Menkul Kıymet'!L159 -> 2.4 | O6: ='Menkul Kıymet'!L160 -> 2.1 | P6: ='Menkul Kıymet'!L161 -> 19.7 | Q6: ='Menkul Kıymet'!L162 -> -27.1 | R6: ='Menkul Kıymet'!L163 -> -29.7 | S6: ='Menkul Kıymet'!L164 -> 16.5 | T6: ='Menkul Kıymet'!L165 -> 5.6 | U6: ='Menkul Kıymet'!L166 -> -21.2 | V6: ='Menkul Kıymet'!L167 -> -2.8 | W6: ='Menkul Kıymet'!L168 -> -6.2 | X6: ='Menkul Kıymet'!L169 -> 8.3 | Y6: ='Menkul Kıymet'!L170 -> 2.8 | Z6: ='Menkul Kıymet'!L171 -> -10.2 | AA6: ='Menkul Kıymet'!L172 -> -3.2 | AD6: =SUM(H6:AA6) -> -58.1
A7: TR Eurobond | B7: ='Menkul Kıymet'!P172 -> 47528.9 | D7: ='Menkul Kıymet'!V144 -> 3645 | H7: ='Menkul Kıymet'!Q153-'Menkul Kıymet'!Q152 -> -586.2 | I7: ='Menkul Kıymet'!Q154-'Menkul Kıymet'!Q153 -> -979.4 | J7: ='Menkul Kıymet'!Q155-'Menkul Kıymet'!Q154 -> -338.3 | K7: ='Menkul Kıymet'!Q156-'Menkul Kıymet'!Q155 -> -184 | L7: ='Menkul Kıymet'!Q157-'Menkul Kıymet'!Q156 -> -46.3 | M7: ='Menkul Kıymet'!Q158-'Menkul Kıymet'!Q157 -> -89.9 | N7: ='Menkul Kıymet'!Q159-'Menkul Kıymet'!Q158 -> -255.1 | O7: ='Menkul Kıymet'!Q160-'Menkul Kıymet'!Q159 -> -29.5 | P7: ='Menkul Kıymet'!Q161-'Menkul Kıymet'!Q160 -> 44.7 | Q7: ='Menkul Kıymet'!Q162-'Menkul Kıymet'!Q161 -> -261.1 | R7: ='Menkul Kıymet'!Q163-'Menkul Kıymet'!Q162 -> -158.3 | S7: ='Menkul Kıymet'!Q164-'Menkul Kıymet'!Q163 -> -639 | T7: ='Menkul Kıymet'!Q165-'Menkul Kıymet'!Q164 -> -274.2 | U7: ='Menkul Kıymet'!Q166-'Menkul Kıymet'!Q165 -> 1540.5 | V7: ='Menkul Kıymet'!Q167-'Menkul Kıymet'!Q166 -> -135.5 | W7: ='Menkul Kıymet'!Q168-'Menkul Kıymet'!Q167 -> 1003.5 | X7: ='Menkul Kıymet'!Q169-'Menkul Kıymet'!Q168 -> -174.5 | Y7: ='Menkul Kıymet'!Q170-'Menkul Kıymet'!Q169 -> -75.9 | Z7: ='Menkul Kıymet'!Q171-'Menkul Kıymet'!Q170 -> -215.6 | AA7: ='Menkul Kıymet'!Q172-'Menkul Kıymet'!Q171 -> -213.7 | AD7: =SUM(H7:AA7) -> -2067.8
A8: Şirket Eurobond | B8: ='Menkul Kıymet'!S172 -> 41498.59 | D8: ='Menkul Kıymet'!V146 -> 1406.19 | H8: ='Menkul Kıymet'!T153-'Menkul Kıymet'!T152 -> -143.7 | I8: ='Menkul Kıymet'!T154-'Menkul Kıymet'!T153 -> 160.6 | J8: ='Menkul Kıymet'!T155-'Menkul Kıymet'!T154 -> -59.2 | K8: ='Menkul Kıymet'!T156-'Menkul Kıymet'!T155 -> 157.3 | L8: ='Menkul Kıymet'!T157-'Menkul Kıymet'!T156 -> -486.3 | M8: ='Menkul Kıymet'!T158-'Menkul Kıymet'!T157 -> -6.5 | N8: ='Menkul Kıymet'!T159-'Menkul Kıymet'!T158 -> -561.8 | O8: ='Menkul Kıymet'!T160-'Menkul Kıymet'!T159 -> 4.5 | P8: ='Menkul Kıymet'!T161-'Menkul Kıymet'!T160 -> 146.6 | Q8: ='Menkul Kıymet'!T162-'Menkul Kıymet'!T161 -> 519 | R8: ='Menkul Kıymet'!T163-'Menkul Kıymet'!T162 -> 210 | S8: ='Menkul Kıymet'!T164-'Menkul Kıymet'!T163 -> 70.95 | T8: ='Menkul Kıymet'!T165-'Menkul Kıymet'!T164 -> -36.83 | U8: ='Menkul Kıymet'!T166-'Menkul Kıymet'!T165 -> -33.02 | V8: ='Menkul Kıymet'!T167-'Menkul Kıymet'!T166 -> 1367.14 | W8: ='Menkul Kıymet'!T168-'Menkul Kıymet'!T167 -> -126.54 | X8: ='Menkul Kıymet'!T169-'Menkul Kıymet'!T168 -> 12.5 | Y8: ='Menkul Kıymet'!T170-'Menkul Kıymet'!T169 -> -71.2 | Z8: ='Menkul Kıymet'!T171-'Menkul Kıymet'!T170 -> 73.89 | AA8: ='Menkul Kıymet'!T172-'Menkul Kıymet'!T171 -> 676.91 | AD8: =SUM(H8:AA8) -> 1874.3
A9: Swap | B9: =Swap!E47 -> 12790 | D9: =Swap!G12 -> 14903 | H9: =Swap!D28 -> -6622 | I9: =Swap!D29 -> -1022 | J9: =Swap!D30 -> 280 | K9: =Swap!D31 -> -98 | L9: =Swap!D32 -> -695 | M9: =Swap!D33 -> -1011 | N9: =Swap!D34 -> 466 | O9: =Swap!D35 -> 103 | P9: =Swap!D36 -> -575 | Q9: =Swap!D37 -> -1323 | R9: =Swap!D38 -> -1308 | S9: =Swap!D39 -> 412 | T9: =Swap!D40 -> -1104 | U9: =Swap!D41 -> 219 | V9: =Swap!D42 -> 180 | W9: =Swap!D43 -> 171 | X9: =Swap!D44 -> 381 | Y9: =Swap!D45 -> -130 | Z9: =Swap!D46 -> 885 | AA9: =Swap!D47 -> -374 | AB9: =Swap!D48 -> 222 | AD9: =SUM(H9:AA9) -> -11165
A10: Toplam | B10: =SUM(B3:B9) -> 134437.99 | D10: =SUM(D3:E9) -> 26877.59 | H10: =SUM(H3:H9) -> -9299.1 | I10: =SUM(I3:I9) -> -2336.6 | J10: =SUM(J3:J9) -> -88.2 | K10: =SUM(K3:K9) -> 230.2 | L10: =SUM(L3:L9) -> -1721.6 | M10: =SUM(M3:M9) -> -906.8 | N10: =SUM(N3:N9) -> -249.5 | O10: =SUM(O3:O9) -> 277.8 | ... AA10: =SUM(AA3:AA9) -> 352.31 | AD10: =SUM(H10:AA10) -> -12327.6
A11: YERLİ
A12: DTH( Arındırılmış) | B12: ='Yerleşik DTH - Kamu Bankaları'!D4 -> 232246 | D12: 8267 | H12: -8125 | I12: ='Yerleşik DTH - Kamu Bankaları'!K4 -> -2024 | J12: ='Yerleşik DTH - Kamu Bankaları'!N4 -> 396 | K12: ='Yerleşik DTH - Kamu Bankaları'!Q4 -> 1345 | L12: ='Yerleşik DTH - Kamu Bankaları'!T4 -> -769 | M12: ='Yerleşik DTH - Kamu Bankaları'!W4 -> -201 | N12: ='Yerleşik DTH - Kamu Bankaları'!Z4 -> 537 | O12: ='Yerleşik DTH - Kamu Bankaları'!AC4 -> 451 | P12: ='Yerleşik DTH - Kamu Bankaları'!AF4 -> -937 | Q12: ='Yerleşik DTH - Kamu Bankaları'!AI4 -> 109 | R12: ='Yerleşik DTH - Kamu Bankaları'!AL4 -> -30 | S12: ='Yerleşik DTH - Kamu Bankaları'!AO4 -> 806 | T12: ='Yerleşik DTH - Kamu Bankaları'!AR4 -> 713 | U12: ='Yerleşik DTH - Kamu Bankaları'!AU4 -> 397 | V12: ='Yerleşik DTH - Kamu Bankaları'!AX4 -> 120 | W12: ='Yerleşik DTH - Kamu Bankaları'!BA4 -> 1724 | X12: ='Yerleşik DTH - Kamu Bankaları'!BD4 -> 1727 | Y12: ='Yerleşik DTH - Kamu Bankaları'!BG4 -> 791 | Z12: ='Yerleşik DTH - Kamu Bankaları'!BJ4 -> 352 | AA12: ='Yerleşik DTH - Kamu Bankaları'!BM4 -> 1664 | AB12: ='Yerleşik DTH - Kamu Bankaları'!BP4 -> 861 | AD12: =SUM(H12:AA12) -> -954
A13: Kamu Bankaları FX Poz | B13: ='Yerleşik DTH - Kamu Bankaları'!D12 -> -137 | D13: 5300 | H13: -422 | I13: 391 | J13: ='Yerleşik DTH - Kamu Bankaları'!H12 -> -24 | K13: ='Yerleşik DTH - Kamu Bankaları'!I12 -> 44.6 | L13: ='Yerleşik DTH - Kamu Bankaları'!J12 -> -98 | M13: ='Yerleşik DTH - Kamu Bankaları'!K12 -> 48 | N13: ='Yerleşik DTH - Kamu Bankaları'!L12 -> 5 | O13: ='Yerleşik DTH - Kamu Bankaları'!M12 -> 15 | P13: ='Yerleşik DTH - Kamu Bankaları'!N12 -> 50 | Q13: ='Yerleşik DTH - Kamu Bankaları'!O12 -> -109 | ... AA13: ='Yerleşik DTH - Kamu Bankaları'!Y12 -> -17 | AD13: =SUM(H13:AA13) -> -202.4
H17: DTH Kümülatif
H18: =SUM(H12) -> -8125 | I18: =SUM(H12+I12) -> -10149 | J18: =SUM(H12:J12) -> -9753 | K18: =SUM(H12:K12) -> -8408 | L18: =SUM(H12:L12) -> -9177 | M18: =SUM(H12:M12) -> -9378 | N18: =SUM(H12:N12) -> -8841 | O18: =SUM(H12:O12) -> -8390 | P18: =SUM(H12:P12) -> -9327 | Q18: =SUM(H12:Q12) -> -9218 | R18: =SUM(H12:R12) -> -9248 | S18: =SUM(H12:S12) -> -8442 | T18: =SUM(H12:T12) -> -7729 | U18: =SUM(H12:U12) -> -7332 | V18: =SUM(H12:V12) -> -7212 | W18: =SUM(H12:W12) -> -5488 | X18: =SUM(H12:X12) -> -3761 | Y18: =SUM(H12:Y12) -> -2970 | Z18: =SUM(H12:Z12) -> -2618 | AA18: =SUM(H12:AA12) -> -954 | AB18: =AA18+AB12 -> -93
M19: ='Menkul Kıymet'!I160 -> 51.7 | N19: ='Menkul Kıymet'!I161 -> 51 | O19: ='Menkul Kıymet'!I162 -> 6.8 | P19: ='Menkul Kıymet'!I163 -> -97.7
M20: ='Menkul Kıymet'!J160 -> 118.5 | N20: ='Menkul Kıymet'!J161 -> 174.8 | O20: ='Menkul Kıymet'!J162 -> 69.2 | P20: ='Menkul Kıymet'!J163 -> -64.1
O21: ='Menkul Kıymet'!K162 -> 267.7 | P21: ='Menkul Kıymet'!K163 -> -13
G22: ='Menkul Kıymet'!L154 -> -4.1 | H22: ='Menkul Kıymet'!L155 -> 3.4 | I22: ='Menkul Kıymet'!L156 -> 18 | J22: ='Menkul Kıymet'!L157 -> -22.1 | K22: ='Menkul Kıymet'!L158 -> 6.5 | O22: ='Menkul Kıymet'!L162 -> -27.1 | P22: ='Menkul Kıymet'!L163 -> -29.7
G25: =Swap!D29 -> -1022 | H25: =Swap!D30 -> 280 | I25: =Swap!D31 -> -98 | J25: =Swap!D32 -> -695 | K25: =Swap!D33 -> -1011 | O25: =Swap!D37 -> -1323 | P25: =Swap!D38 -> -1308

Sheet Yerleşik DTH - Kamu Bankaları
F1: KOVULMA SONRASI - Bireysel DTHlar ARINDIRILMIŞ DEĞİŞİM
F2: 44281 | I2: 44288 | L2: 44295 | O2: 44302 | R2: 44308 | U2: 44316 | X2: 44323 | AA2: 44330 | AD2: 44337 | AG2: 44344 | AJ2: 44351 | AM2: 44358 | AP2: 44365 | AS2: 44372 | AV2: 44379 | AY2: 44386 | BB2: 44393 | BE2: 44396 | BH2: 44407 | BK2: 44414 | BN2: 44421
A3: 6 Kasım Sonrası Artış(Arındırılmamış) | C3: Yerleşikler DTH | D3: STOK(13.08.2021) | F3: Birey | G3: Tüzel | H3: Arındırılmış | I3: Birey | J3: Tüzel | K3: Arındırılmış | L3: Birey | M3: Tüzel | N3: Arındırılmış | O3: Birey | P3: Tüzel | Q3: Arındırılmış | R3: Birey | S3: Tüzel | T3: Arındırılmış | U3: Birey | V3: Tüzel | W3: Arındırılmış | X3: Birey | Y3: Tüzel | Z3: Arındırılmış | AA3: Birey | AB3: Tüzel | AC3: Arındırılmış | AD3: Birey | AE3: Tüzel | AF3: Arındırılmış | AG3: Birey | AH3: Tüzel | AI3: Arındırılmış | AJ3: Birey | AK3: Tüzel | AL3: Arındırılmış | AM3: Birey | AN3: Tüzel | AO3: Arındırılmış | AP3: Birey | AQ3: Tüzel | AR3: Arındırılmış | AS3: Birey | AT3: Tüzel | AU3: Arındırılmış | AV3: Birey | AW3: Tüzel | AX3: Arındırılmış | AY3: Birey | AZ3: Tüzel | BA3: Arındırılmış | BB3: Birey | BC3: Tüzel | BD3: Arındırılmış | BE3: Birey | BF3: Tüzel | BG3: Arındırılmış | BH3: Birey | BI3: Tüzel | BJ3: Arındırılmış | BK3: Birey | BL3: Tüzel | BM3: Arındırılmış | BN3: Birey | BO3: Tüzel | BP3: Arındırılmış
A4: 8267 | D4: 232246 | F4: -6740 | G4: -1385 | H4: =F4+G4 -> -8125 | I4: -718 | J4: -1306 | K4: =I4+J4 -> -2024 | L4: -509 | M4: 905 | N4: =L4+M4 -> 396 | O4: 257 | P4: 1088 | Q4: 1345 | R4: -20 | S4: -749 | T4: -769 | U4: 33 | V4: -269 | W4: -201 | X4: -83 | Y4: 620 | Z4: 537 | AA4: 118 | AB4: 334 | AC4: 451 | AD4: -550 | AE4: -387 | AF4: -937 | AG4: 275 | AH4: -166 | AI4: 109 | AJ4: 456 | AK4: -485 | AL4: -30 | AM4: -101 | AN4: 907 | AO4: 806 | AP4: 455 | AQ4: 258 | AR4: 713 | AS4: 340 | AT4: 57 | AU4: 397 | AV4: 340 | AW4: -222 | AX4: 120 | AY4: 288 | AZ4: 1437 | BA4: 1724 | BB4: 732 | BC4: 995 | BD4: =BB4+BC4 -> 1727 | BE4: 494 | BF4: 297 | BG4: =BE4+BF4 -> 791 | BH4: 327 | BI4: 25 | BJ4: 352 | BK4: 701 | BL4: 963 | BM4: 1664 | BN4: 580 | BO4: 281 | BP4: 861
F10: Kamu Bankaları FX Pozisyon Değişimi | O10: KAMU BANKASI FX POZİSYONLARINDAKİ DEĞİŞİM
A11: Kamu Bankaları FX Poz | D11: STOK(13.08.2021) | F11: 44281 | G11: 44288 | H11: 44295 | I11: 44302 | J11: 44308 | K11: 44316 | L11: 44323 | M11: 44330 | N11: 44337 | O11: 44344 | P11: 44351 | Q11: 44358 | R11: 44365 | S11: 44372 | T11: 44379 | U11: 44386 | V11: 44393 | W11: 44396 | X11: 44407 | Y11: 44414 | Z11: 44421
A12: 6 Kasım Sonrası ne kadar aldı ? | D12: -137 | F12: -422 | G12: =328+63 -> 391 | H12: -24 | I12: 44.6 | J12: -98 | K12: 48 | L12: 5 | M12: 15 | N12: 50 | O12: -109 | P12: 9 | Q12: 220 | R12: -20 | S12: -60 | T12: -16 | U12: -92 | V12: -180 | W12: 10 | X12: 43 | Y12: -17 | Z12: -30
A13: =94-(-5206) -> 5300

Sheet Swap
A1: TARİH | B1: Swap Para Alım - TL | C1: Swap Para Satım - TL | D1: Net Para Satım - TL | E1: TCMB Swap | F1: Y.Dışı yerleşikler Swap Stok | G1: Haluk Bürükçekçi Verileri | K1: bddk aylık rapor
A2: 12'2017 | B2: 40991 | C2: 88052 | D2: =C2-B2 -> 47061 | E2: 0 | F2: =D2-E2 -> 47061 | K2: Bilanço dışı İşlemler :USD BAZINDA
A3: 12'2018 | B3: 22565 | C3: 59554 | D3: =C3-B3 -> 36989 | E3: 264 | F3: =D3-E3 -> 36725 | K3: Para Swapları
A4: 12'2019 | B4: 15946 | C4: 60193 | D4: =C4-B4 -> 44247 | E4: 12310 | F4: =D4-E4 -> 31937 | K4: Swap Para Alım
A5: 10'2020 | B5: 7233 | C5: 59116 | D5: =C5-B5 -> 51883 | E5: 49900 | F5: =D5-E5 -> 1983 | K5: Swap Para satım
A6: 11'2020 | B6: 8807 | C6: 67361 | D6: =C6-B6 -> 58554 | E6: 46400 | F6: =D6-E6 -> 12154
A7: 12'2020 | B7: 9458 | C7: 74109 | D7: =C7-B7 -> 64651 | E7: 44300 | F7: =D7-E7 -> 20351
A11: TARİH | B11: TCMB TARAFLI SWAP STOĞU( Günlük ) | C11: BDDK = Bilanço Dışı YP( Haftalık ) | D11: Haftalık Carry Trade poz. Değişimi | E11: Y.Dışı yerleşikler Swap Stok | G11: 6 Kasım Sonrası Giren Carry Poz
A12: Eylül'20 | B12: 45387 | C12: 54439 | E12: =C12-B12 -> 9052 | G12: =SUM(D13:D26) -> 14903
A13: Ekim'20 | B13: 49353 | C13: 58556 | D13: =(C13-C12)-(B13-B12) -> 151 | E13: =C13-B13 -> 9203
A14: Kasım'20 | B14: 45928 | C14: 62252 | D14: =(C14-C13)-(B14-B13) -> 7121 | E14: =C14-B14 -> 16324
A15: Aralık'20 | B15: 44428 | C15: 66852 | D15: =(C15-C14)-(B15-B14) -> 6100 | E15: =C15-B15 -> 22424 | G15: Source
A16: 44204 | B16: 43601 | C16: 65329 | D16: =(C16-C15)-(B16-B15) -> -696 | E16: =C16-B16 -> 21728 | G16: TCMB Taraflı Swap İşlemleri
A17: 44211 | B17: 43447 | C17: 65194 | D17: =(C17-C16)-(B17-B16) -> 19 | E17: =C17-B17 -> 21747 | G17: BDDK = BDYP
A18: 44218 | B18: 42363 | C18: 65453 | D18: =(C18-C17)-(B18-B17) -> 1343 | E18: =C18-B18 -> 23090
A19: 44225 | B19: 41590 | C19: 64835 | D19: =(C19-C18)-(B19-B18) -> 155 | E19: =C19-B19 -> 23245
A20: 44232 | B20: 41176 | C20: 64162 | D20: =(C20-C19)-(B20-B19) -> -259 | E20: =C20-B20 -> 22986 | G20: Önceki Verileri şu şekilde buluyoruz
A21: 44239 | B21: 40160 | C21: 63922 | D21: =(C21-C20)-(B21-B20) -> 776 | E21: =C21-B21 -> 23762 | G21: UA Rezervler tablosu ( Aylık ) ndaki Swaplar - Yabancı MB Swapları | O21: BDYP = Ayın son haftası olarak alınıyor
A22: 44246 | B22: 39899 | C22: 64173 | D22: =(C22-C21)-(B22-B21) -> 512 | E22: =C22-B22 -> 24274
A23: 44253 | B23: 40389 | C23: 63153 | D23: =(C23-C22)-(B23-B22) -> -1510 | E23: =C23-B23 -> 22764 | G23: 2. Yurt içi para karşılığında döviz forward ve future'ların toplam açık ve fazla pozisyon büyüklükleri (para swaplarının gelecekteki bacağını da kapsar) ++++++3. Diğer == SWAPLAR
A24: 44260 | B24: 40305 | C24: 63091 | D24: =(C24-C23)-(B24-B23) -> 22 | E24: =C24-B24 -> 22786 | G24: Yabancı MB Swapları : 17,5B USD
A25: 44267 | B25: 40170 | C25: 62825 | D25: =(C25-C24)-(B25-B24) -> -131 | E25: =C25-B25 -> 22655
A26: 44274 | B26: 44786 | C26: 68741 | D26: =(C26-C25)-(B26-B25) -> 1300 | E26: =C26-B26 -> 23955
A27: N. Ağbal'ın Kovulması
A28: 44281 | B28: 42779 | C28: 60112 | D28: =(C28-C26)-(B28-B26) -> -6622 | E28: =C28-B28 -> 17333
A29: 44288 | B29: 42721 | C29: 59032 | D29: =(C29-C28)-(B29-B28) -> -1022 | E29: =C29-B29 -> 16311
A30: 44295 | B30: 41961 | C30: 58552 | D30: =(C30-C29)-(B30-B29) -> 280 | E30: =C30-B30 -> 16591
A31: 44302 | B31: 42328 | C31: 58821 | D31: =(C31-C30)-(B31-B30) -> -98 | E31: =C31-B31 -> 16493
A32: 44308 | B32: 42432 | C32: 58230 | D32: =(C32-C31)-(B32-B31) -> -695 | E32: =C32-B32 -> 15798
A33: 44316 | B33: 43217 | C33: 58004 | D33: =(C33-C32)-(B33-B32) -> -1011 | E33: =C33-B33 -> 14787
A34: 44323 | B34: 42279 | C34: 57532 | D34: =(C34-C33)-(B34-B33) -> 466 | E34: =C34-B34 -> 15253
A35: 44328 | B35: 42298 | C35: 57654 | D35: =(C35-C34)-(B35-B34) -> 103 | E35: =C35-B35 -> 15356
A36: 44337 | B36: 42514 | C36: 57295 | D36: =(C36-C35)-(B36-B35) -> -575 | E36: =C36-B36 -> 14781
A37: 44344 | B37: 42317 | C37: 55775 | D37: =(C37-C36)-(B37-B36) -> -1323 | E37: =C37-B37 -> 13458
A38: 44351 | B38: 44400 | C38: 56550 | D38: =(C38-C37)-(B38-B37) -> -1308 | E38: =C38-B38 -> 12150
A39: 44358 | B39: 45204 | C39: 57766 | D39: =(C39-C38)-(B39-B38) -> 412 | E39: =C39-B39 -> 12562
A40: 44365 | B40: 45735 | C40: 57193 | D40: =(C40-C39)-(B40-B39) -> -1104 | E40: =C40-B40 -> 11458
... A48: 44421 | B48: 44845 | C48: 57857 | D48: =(C48-C47)-(B48-B47) -> 222 | E48: =C48-B48 -> 13012

Sheet Credit
A1: HER PERŞEMBE | C1: Tüketici Kredileri ve Bireysel Kredi Kartları (3+7) | D1: Ticari ve Diğer Krediler | E1: Bireysel Krediler(USD) | F1: Ticari Krediler(USD) | G1: USDTRY | H1: Krediler / Toplam Krediler (2+10) | I1: Aylık Kredi Flowu(TL) | J1: Haftalık Kredi Flowu ( TL ) | K1: Haftalık Kredi Flowu ( TL )/ TOTAL Kredi Stoğu | L1: Aylık TL Kredi Flowu(USDBazında) | M1: Aylık TL Kredi Flowu(USD Bazında ) + Aylık USD Flowu | N1: YP Flow minus TL Kredi Flow ( USD Eq.) | O1: Aylık Kredi Flowu ( TL )/ TOTAL Kredi Stoğu | P1: Toplam MoM % | Q1: Toplam YoY % | S1: Tüketici Kredileri MoM % | T1: Tüketici YoY % | U1: 13-WEEK GROWTH - Tüketici | V1: Haftalık Tüketici Flowu / Haftalık Toplam Flow | W1: Aylık Tüketici Flowu Aylık Total Flowun Kaçı | X1: Ticari Krediler MoM % | Y1: Ticari YoY % | Z1: 13-WEEK GROWTH - Ticari | AA1: Haftalık Ticari Flowu / Haftalık Toplam Flow | AB1: Haftalık Ticari Flowu Haftalık total Flowun kaçı 13w Avg | AC1: Haftalık Tükecii Flowu Haftalık Total Flowun kaçı 13w Avg | AD1: Aylık ticari Flowu Aylık Total Flowun Kaçı | AE1: 13 Week MA | AF1: 13 W Kredi MoM % | AG1: 13 W Kredi YoY % | AH1: YP KREDİLER (Dolar Bazında) | AI1: Ticari Krediler(TL Ederi) | AJ1: USD Bazlı - Ticari Krediler Aylık Büyüme | AK1: Aylık USD Artış | AL1: Haftalık USD Artış | AM1: Haftalık USD Artış - TL Ederi | AN1: Aylık Artışı TL Ederi | AO1: USD Kredi Total TL Değeri | AP1: TL Kredi Total / FX Kredi
A2: BDDK BÜLTEN | B2: 41999 | C2: 353346.2 | D2: 526178.83 | E2: 112.16 | F2: 155463.25 | G2: 2.31884 | H2: 879525.03 | K2: =J2/H2 -> 0 | O2: =I2/H2 -> 0 | V2: =(C2-C1)/H2 -> #VALUE! | W2: =(C2-#REF!)/(H2-#REF!) -> #REF! | AA2: =(D2-D1)/O2 -> #VALUE! | AD2: =(D2-#REF!)/(H2-#REF!) -> #REF! | AI2: =F2*G2 -> 360494.4 | AO2: =(E2+F2)*G2 -> 360754.48 | AP2: =H2/AO2 -> 2.4380155
B3: 42006 | C3: 355760.74 | D3: 519487.04 | E3: 109.33 | F3: 154576.58 | G3: 2.321875 | H3: 875247.77 | J3: =H3-H2 -> -4277.26 | K3: =J3/H3 -> -0.0048869133 | O3: =I3/H3 -> 0 | V3: =(C3-C2)/H3 -> 0.0027586931 | W3: =(C3-#REF!)/(H3-#REF!) -> #REF! | AA3: =(D3-D2)/O3 -> #DIV/0! | AD3: =(D3-#REF!)/(H3-#REF!) -> #REF! | AI3: =F3*G3 -> 358907.5 | AL3: =F3-F2 -> -886.67 | AM3: =AL3*G3 -> -2058.7369 | AO3: =(E3+F3)*G3 -> 359161.35 | AP3: =H3/AO3 -> 2.4369208
B4: 42013 | C4: 355131.13 | D4: 518851.38 | E4: 110.28 | F4: 153907.65 | G4: 2.32936 | H4: 873982.51 | J4: =H4-H3 -> -1265.26 | K4: =J4/H4 -> -0.0014476949 | O4: =I4/H4 -> 0 | V4: =(C4-C3)/(H4-H3) -> 0.49761314 | W4: =(C4-#REF!)/(H4-#REF!) -> #REF! | AA4: =(D4-D3)/O4 -> #DIV/0! | AD4: =(D4-#REF!)/(H4-#REF!) -> #REF! | AI4: =F4*G4 -> 358506.32 | AL4: =F4-F3 -> -668.93 | AM4: =AL4*G4 -> -1558.1788 | AO4: =(E4+F4)*G4 -> 358763.21 | AP4: =H4/AO4 -> 2.4360985
B5: 42020 | C5: 354536.18 | D5: 525016.71 | E5: 113.63 | F5: 153013.97 | G5: 2.28808 | H5: 879552.89 | J5: =H5-H4 -> 5570.38 | K5: =J5/H5 -> 0.006333195 | O5: =I5/H5 -> 0 | V5: =(C5-C4)/(H5-H4) -> -0.106806 | W5: =(C5-C1)/(H5-H1) -> #VALUE! | AA5: =(D5-D4)/O5 -> #DIV/0! | AD5: =(D5-D1)/(H5-H1) -> #VALUE! | AI5: =F5*G5 -> 350108.2 | AL5: =F5-F4 -> -893.68 | AM5: =AL5*G5 -> -2044.8113 | AO5: =(E5+F5)*G5 -> 350368.2 | AP5: =H5/AO5 -> 2.5103674
B6: 42027 | C6: 355250.21 | D6: 522413.23 | E6: 115.58 | F6: 152033.36 | G6: 2.33364 | H6: 877663.44 | I6: =H6-H2 -> -1861.59 | J6: =H6-H5 -> -1889.45 | K6: =J6/H6 -> -0.0021528184 | L6: =I6/G6 -> -797.71944 | M6: =L6+AK6 -> -4227.6094 | N6: =AK6-L6 -> -2632.1706 | O6: =I6/H6 -> -0.002121075 | P6: =(H6-H2)/H2 -> -0.0021165856 | S6: =(C6-C2)/C2 -> 0.0053885113 | V6: =(C6-C5)/(H6-H5) -> -0.37790362 | W6: =(C6-C2)/(H6-H2) -> -1.022787 | X6: =(D6-D2)/D2 -> -0.0071565023 | AA6: =(D6-D5)/(H6-H5) -> 1.3779036 | AF6: =(AE6-AE2)/AE2 -> #DIV/0! | AI6: =F6*G6 -> 354791.13 | AJ6: =(AI6-AI2)/AI2 -> -0.015820696 | AK6: =(F6-F2) -> -3429.89 | AL6: =F6-F5 -> -980.61 | AM6: =AL6*G6 -> -2288.3907 | AN6: =AK6*G6 -> -8004.1285 | AO6: =(E6+F6)*G6 -> 355060.85 | AP6: =H6/AO6 -> 2.4718677
B7: 42034 | C7: 357986.9 | D7: 529374.76 | E7: 114.19 | F7: 152437.86 | G7: 2.36258 | H7: 887361.66 | I7: =H7-H3 -> 12113.89 | J7: =H7-H6 -> 9698.22 | K7: =J7/H7 -> 0.010929275 | L7: =I7/G7 -> 5127.3989 | M7: =L7+AK7 -> 2988.6789 | N7: =AK7-L7 -> -7266.1189 | O7: =I7/H7 -> 0.013651581 | P7: =(H7-H3)/H3 -> 0.013840527 | S7: =(C7-C3)/C3 -> 0.0062574639 | V7: =(C7-C6)/(H7-H6) -> 0.28218477 | W7: =(C7-C3)/(H7-H3) -> 0.18376921 | X7: =(D7-D3)/D3 -> 0.019033622 | AA7: =(D7-D6)/(H7-H6) -> 0.71781523 | AD7: =(D7-D3)/(H7-H3) -> 0.81622996 | AF7: =(AE7-AE3)/AE3 -> #DIV/0! | AI7: =F7*G7 -> 360146.64 | AJ7: =(AI7-AI3)/AI3 -> 0.0034525403 | AK7: =(F7-F3) -> -2138.72 | AL7: =F7-F6 -> 404.5 | AM7: =AL7*G7 -> 955.66361 | AN7: =AK7*G7 -> -5052.8971 | AO7: =(E7+F7)*G7 -> 360416.42 | AP7: =H7/AO7 -> 2.4620456
B8: 42041 | C8: 358441.15 | D8: 529300.33 | E8: 80.81 | F8: 153178.82 | G8: 2.42202 | H8: 887741.48 | I8: =H8-H4 -> 13758.97 | J8: =H8-H7 -> 379.82 | K8: =J8/H8 -> 0.00042784978 | L8: =I8/G8 -> 5680.783 | M8: =L8+AK8 -> 4951.953 | N8: =AK8-L8 -> -6409.613 | O8: =I8/H8 -> 0.015498848 | P8: =(H8-H4)/H4 -> 0.015742844 | S8: =(C8-C4)/C4 -> 0.0093205572 | V8: =(C8-C7)/(H8-H7) -> 1.1959612 | W8: =(C8-C4)/(H8-H4) -> 0.24057179 | X8: =(D8-D4)/D4 -> 0.020138618 | AA8: =(D8-D7)/(H8-H7) -> -0.19596124 | AD8: =(D8-D4)/(H8-H4) -> 0.75942821 | AF8: =(AE8-AE4)/AE4 -> #DIV/0! | AI8: =F8*G8 -> 371002.17 | AJ8: =(AI8-AI4)/AI4 -> 0.03485529 | AK8: =(F8-F4) -> -728.83 | AL8: =F8-F7 -> 740.96 | AM8: =AL8*G8 -> 1794.6199 | AN8: =AK8*G8 -> -1765.2408 | AO8: =(E8+F8)*G8 -> 371197.89 | AP8: =H8/AO8 -> 2.3915585
B9: 42048 | C9: 360437.67 | D9: 534725.62 | E9: 86.27 | F9: 153528.26 | G9: 2.47554 | H9: 895163.29 | I9: =H9-H5 -> 15610.4 | J9: =H9-H8 -> 7421.81 | K9: =J9/H9 -> 0.0082910125 | L9: =I9/G9 -> 6305.8565 | M9: =L9+AK9 -> 6820.1465 | N9: =AK9-L9 -> -5791.5665 | O9: =I9/H9 -> 0.017438606 | P9: =(H9-H5)/H5 -> 0.017748108 | S9: =(C9-C5)/C5 -> 0.016645664 | V9: =(C9-C8)/(H9-H8) -> 0.26900716 | W9: =(C9-C5)/(H9-H5) -> 0.37804861 | X9: =(D9-D5)/D5 -> 0.018492573 | AA9: =(D9-D8)/(H9-H8) -> 0.73099284 | AD9: =(D9-D5)/(H9-H5) -> 0.62195139 | AF9: =(AE9-AE5)/AE5 -> #DIV/0! | AI9: =F9*G9 -> 380065.35 | AJ9: =(AI9-AI5)/AI5 -> 0.085565388 | AK9: =(F9-F5) -> 514.29 | AL9: =F9-F8 -> 349.44 | AM9: =AL9*G9 -> 865.0527 | AN9: =AK9*G9 -> 1273.1455 | AO9: =(E9+F9)*G9 -> 380278.91 | AP9: =H9/AO9 -> 2.3539651
B10: 42055 | C10: 358500.17 | D10: 536262.33 | E10: 86.9 | F10: 153622.3 | G10: 2.45428 | H10: 894762.5 | I10: =H10-H6 -> 17099.06 | J10: =H10-H9 -> -400.79 | K10: =J10/H10 -> -0.00044792892 | L10: =I10/G10 -> 6967.0372 | M10: =L10+AK10 -> 8555.9772 | N10: =AK10-L10 -> -5378.0972 | O10: =I10/H10 -> 0.019110166 | P10: =(H10-H6)/H6 -> 0.01948248 | S10: =(C10-C6)/C6 -> 0.009148369 | V10: =(C10-C9)/(H10-H9) -> 4.8342025 | W10: =(C10-C6)/(H10-H6) -> 0.19006659 | X10: =(D10-D6)/D6 -> 0.026509857 | AA10: =(D10-D9)/(H10-H9) -> -3.8342025 | AD10: =(D10-D6)/(H10-H6) -> 0.80993341 | AF10: =(AE10-AE6)/AE6 -> #DIV/0! | AI10: =F10*G10 -> 377032.14 | AJ10: =(AI10-AI6)/AI6 -> 0.062687611 | AK10: =(F10-F6) -> 1588.94 | AL10: =F10-F9 -> 94.04 | AM10: =AL10*G10 -> 230.80049 | AN10: =AK10*G10 -> 3899.7037 | AO10: =(E10+F10)*G10 -> 377245.42 | AP10: =H10/AO10 -> 2.3718313
B11: 42062 | C11: 359676.33 | D11: 544017.13 | E11: 78.33 | F11: 153759.37 | G11: 2.46906 | H11: 903693.45 | I11: =H11-H7 -> 16331.79 | J11: =H11-H10 -> 8930.95 | K11: =J11/H11 -> 0.0098827207 | L11: =I11/G11 -> 6614.578 | M11: =L11+AK11 -> 7936.088 | N11: =AK11-L11 -> -5293.068 | O11: =I11/H11 -> 0.018072268 | P11: =(H11-H7)/H7 -> 0.018404886 | S11: =(C11-C7)/C7 -> 0.0047192509 | V11: =(C11-C10)/(H11-H10) -> 0.13169484 | W11: =(C11-C7)/(H11-H7) -> 0.10344426 | X11: =(D11-D7)/D7 -> 0.027659743 | AA11: =(D11-D10)/(H11-H10) -> 0.86830628 | AD11: =(D11-D7)/(H11-H7) -> 0.89655635 | AF11: =(AE11-AE7)/AE7 -> #DIV/0! | AI11: =F11*G11 -> 379641.11 | AJ11: =(AI11-AI7)/AI7 -> 0.054129259 | AK11: =(F11-F7) -> 1321.51 | AL11: =F11-F10 -> 137.07 | AM11: =AL11*G11 -> 338.43405 | AN11: =AK11*G11 -> 3262.8875 | AO11: =(E11+F11)*G11 -> 379834.51 | AP11: =H11/AO11 -> 2.3791768
B12: 42069 | C12: 360105.04 | D12: 544398.71 | E12: 74.8 | F12: 152999.76 | G12: 2.53216 | H12: 904503.75 | I12: =H12-H8 -> 16762.27 | J12: =H12-H11 -> 810.3 | K12: =J12/H12 -> 0.00089585035 | L12: =I12/G12 -> 6619.7515 | M12: =L12+AK12 -> 6440.6915 | N12: =AK12-L12 -> -6798.8115 | O12: =I12/H12 -> 0.018532007 | P12: =(H12-H8)/H8 -> 0.018881927 | S12: =(C12-C8)/C8 -> 0.0046420172 | V12: =(C12-C11)/(H12-H11) -> 0.52907565 | W12: =(C12-C8)/(H12-H8) -> 0.099264002 | X12: =(D12-D8)/D8 -> 0.028525166 | AA12: =(D12-D11)/(H12-H11) -> 0.47091201 | AD12: =(D12-D8)/(H12-H8) -> 0.900736 | AF12: =(AE12-AE8)/AE8 -> #DIV/0! | AI12: =F12*G12 -> 387419.87 | AJ12: =(AI12-AI8)/AI8 -> 0.04425232 | AK12: =(F12-F8) -> -179.06 | AL12: =F12-F11 -> -759.61 | AM12: =AL12*G12 -> -1923.4541 | AN12: =AK12*G12 -> -453.40857 | AO12: =(E12+F12)*G12 -> 387609.28 | AP12: =H12/AO12 -> 2.3335451
B13: 42076 | C13: 361482.74 | D13: 547221.3 | E13: 105.97 | F13: 151756.57 | G13: 2.60754 | H13: 908704.04 | I13: =H13-H9 -> 13540.75 | J13: =H13-H12 -> 4200.29 | K13: =J13/H13 -> 0.004622286 | L13: =I13/G13 -> 5192.9213 | M13: =L13+AK13 -> 3421.2313 | N13: =AK13-L13 -> -6964.6113 | O13: =I13/H13 -> 0.014901166 | P13: =(H13-H9)/H9 -> 0.01512657 | S13: =(C13-C9)/C9 -> 0.0028994472 | V13: =(C13-C12)/(H13-H12) -> 0.32800116 | W13: =(C13-C9)/(H13-H9) -> 0.077179624 | X13: =(D13-D9)/D9 -> 0.023368396 | AA13: =(D13-D12)/(H13-H12) -> 0.67199884 | AD13: =(D13-D9)/(H13-H9) -> 0.92282038 | AF13: =(AE13-AE9)/AE9 -> #DIV/0! | AI13: =F13*G13 -> 395711.33 | AJ13: =(AI13-AI9)/AI9 -> 0.041166546 | AK13: =(F13-F9) -> -1771.69 | AL13: =F13-F12 -> -1243.19 | AM13: =AL13*G13 -> -3241.6677 | AN13: =AK13*G13 -> -4619.7525 | AO13: =(E13+F13)*G13 -> 395987.65 | AP13: =H13/AO13 -> 2.2947788
B14: 42083 | C14: 360704.08 | D14: 548372.33 | E14: 109.45 | F14: 152777.4 | G14: 2.61184 | H14: 909076.41 | I14: =H14-H10 -> 14313.91 | J14: =H14-H13 -> 372.37 | K14: =J14/H14 -> 0.00040961353 | L14: =I14/G14 -> 5480.3931 | M14: =L14+AK14 -> 4635.4931 | N14: =AK14-L14 -> -6325.2931 | O14: =I14/H14 -> 0.015745552 | P14: =(H14-H10)/H10 -> 0.015997441 | S14: =(C14-C10)/C10 -> 0.0061475843 | V14: =(C14-C13)/(H14-H13) -> -2.0910922 | W14: =(C14-C10)/(H14-H10) -> 0.15396981 | X14: =(D14-D10)/D10 -> 0.022582231 | AA14: =(D14-D13)/(H14-H13) -> 3.0910922 | AB14: =AVERAGE(AA2:AA14) -> #VALUE! | AC14: =AVERAGE(V2:V14) -> #VALUE! | AD14: =(D14-D10)/(H14-H10) -> 0.84603019 | AE14: =AVERAGE(H2:H14) -> 890536.79 | AF14: =(AE14-AE10)/AE10 -> #DIV/0! | AI14: =F14*G14 -> 399030.12 | AJ14: =(AI14-AI10)/AI10 -> 0.058345122 | AK14: =(F14-F10) -> -844.9 | AL14: =F14-F13 -> 1020.83 | AM14: =AL14*G14 -> 2666.2446 | AN14: =AK14*G14 -> -2206.7436 | AO14: =(E14+F14)*G14 -> 399315.99 | AP14: =H14/AO14 -> 2.276584
